Internal Server Error: /api/users/test+2@examples.com
Traceback (most recent call last):
  File "/usr/local/lib/python3.9/site-packages/django/core/handlers/exception.py", line 55, in inner
    response = get_response(request)
  File "/usr/local/lib/python3.9/site-packages/django/utils/deprecation.py", line 136, in __call__
    response = self.process_response(request, response)
  File "/usr/local/lib/python3.9/site-packages/django/middleware/common.py", line 108, in process_response
    return self.response_redirect_class(self.get_full_path_with_slash(request))
  File "/usr/local/lib/python3.9/site-packages/django/middleware/common.py", line 87, in get_full_path_with_slash
    raise RuntimeError(
RuntimeError: You called this URL via PUT, but the URL doesn't end in a slash and you have APPEND_SLASH set. Django can't redirect to the slash URL while maintaining PUT data. Change your form to point to localhost:7777/api/users/test+2@examples.com/ (note the trailing slash), or set APPEND_SLASH=False in your Django settings.
"PUT /api/users/test+2@examples.com HTTP/1.1" 500 64090
Internal Server Error: /api/users/update
Traceback (most recent call last):
  File "/usr/local/lib/python3.9/site-packages/django/core/handlers/exception.py", line 55, in inner
    response = get_response(request)
  File "/usr/local/lib/python3.9/site-packages/django/core/handlers/base.py", line 197, in _get_response
    response = wrapped_callback(request, *callback_args, **callback_kwargs)
  File "/usr/local/lib/python3.9/site-packages/django/views/decorators/csrf.py", line 56, in wrapper_view
    return view_func(*args, **kwargs)
  File "/usr/local/lib/python3.9/site-packages/django/views/generic/base.py", line 104, in view
    return self.dispatch(request, *args, **kwargs)
  File "/usr/local/lib/python3.9/site-packages/rest_framework/views.py", line 511, in dispatch
    self.response = self.finalize_response(request, response, *args, **kwargs)
  File "/usr/local/lib/python3.9/site-packages/rest_framework/views.py", line 423, in finalize_response
    assert isinstance(response, HttpResponseBase), (
AssertionError: Expected a `Response`, `HttpResponse` or `HttpStreamingResponse` to be returned from the view, but received a `<class 'str'>`
"PUT /api/users/update?email=test+2@examples.com HTTP/1.1" 500 73420
"PUT /api/users/update?email=test+2@examples.com HTTP/1.1" 500 59
"PUT /api/users/update?email=test@examples.com HTTP/1.1" 500 59
Internal Server Error: /api/users
"GET /api/users HTTP/1.1" 500 91
Internal Server Error: /api/users/update
Traceback (most recent call last):
  File "/usr/local/lib/python3.9/site-packages/django/core/handlers/exception.py", line 55, in inner
    response = get_response(request)
  File "/usr/local/lib/python3.9/site-packages/django/utils/deprecation.py", line 136, in __call__
    response = self.process_response(request, response)
  File "/usr/local/lib/python3.9/site-packages/django/middleware/common.py", line 108, in process_response
    return self.response_redirect_class(self.get_full_path_with_slash(request))
  File "/usr/local/lib/python3.9/site-packages/django/middleware/common.py", line 87, in get_full_path_with_slash
    raise RuntimeError(
RuntimeError: You called this URL via PUT, but the URL doesn't end in a slash and you have APPEND_SLASH set. Django can't redirect to the slash URL while maintaining PUT data. Change your form to point to localhost:7777/api/users/update/?email=test@examples.com (note the trailing slash), or set APPEND_SLASH=False in your Django settings.
"PUT /api/users/update?email=test@examples.com HTTP/1.1" 500 64471
Internal Server Error: /api/users/update
Traceback (most recent call last):
  File "/usr/local/lib/python3.9/site-packages/django/core/handlers/exception.py", line 55, in inner
    response = get_response(request)
  File "/usr/local/lib/python3.9/site-packages/django/utils/deprecation.py", line 136, in __call__
    response = self.process_response(request, response)
  File "/usr/local/lib/python3.9/site-packages/django/middleware/common.py", line 108, in process_response
    return self.response_redirect_class(self.get_full_path_with_slash(request))
  File "/usr/local/lib/python3.9/site-packages/django/middleware/common.py", line 87, in get_full_path_with_slash
    raise RuntimeError(
RuntimeError: You called this URL via PUT, but the URL doesn't end in a slash and you have APPEND_SLASH set. Django can't redirect to the slash URL while maintaining PUT data. Change your form to point to localhost:7777/api/users/update/?email=user@example.com (note the trailing slash), or set APPEND_SLASH=False in your Django settings.
"PUT /api/users/update?email=user@example.com HTTP/1.1" 500 64459
Internal Server Error: /api/users/c3daef55-72c6-4cc5-8924-616063dd51c8}
Traceback (most recent call last):
  File "/usr/local/lib/python3.9/site-packages/django/core/handlers/exception.py", line 55, in inner
    response = get_response(request)
  File "/usr/local/lib/python3.9/site-packages/django/utils/deprecation.py", line 136, in __call__
    response = self.process_response(request, response)
  File "/usr/local/lib/python3.9/site-packages/django/middleware/common.py", line 108, in process_response
    return self.response_redirect_class(self.get_full_path_with_slash(request))
  File "/usr/local/lib/python3.9/site-packages/django/middleware/common.py", line 87, in get_full_path_with_slash
    raise RuntimeError(
RuntimeError: You called this URL via PUT, but the URL doesn't end in a slash and you have APPEND_SLASH set. Django can't redirect to the slash URL while maintaining PUT data. Change your form to point to localhost:7777/api/users/c3daef55-72c6-4cc5-8924-616063dd51c8%7D/ (note the trailing slash), or set APPEND_SLASH=False in your Django settings.
"PUT /api/users/c3daef55-72c6-4cc5-8924-616063dd51c8%7D HTTP/1.1" 500 64400
Internal Server Error: /api/users
Traceback (most recent call last):
  File "/usr/local/lib/python3.9/site-packages/django/core/handlers/exception.py", line 55, in inner
    response = get_response(request)
  File "/usr/local/lib/python3.9/site-packages/django/utils/deprecation.py", line 136, in __call__
    response = self.process_response(request, response)
  File "/usr/local/lib/python3.9/site-packages/django/middleware/common.py", line 108, in process_response
    return self.response_redirect_class(self.get_full_path_with_slash(request))
  File "/usr/local/lib/python3.9/site-packages/django/middleware/common.py", line 87, in get_full_path_with_slash
    raise RuntimeError(
RuntimeError: You called this URL via PUT, but the URL doesn't end in a slash and you have APPEND_SLASH set. Django can't redirect to the slash URL while maintaining PUT data. Change your form to point to localhost:7777/api/users/ (note the trailing slash), or set APPEND_SLASH=False in your Django settings.
"PUT /api/users HTTP/1.1" 500 62510
Internal Server Error: /api/users
Traceback (most recent call last):
  File "/usr/local/lib/python3.9/site-packages/django/core/handlers/exception.py", line 55, in inner
    response = get_response(request)
  File "/usr/local/lib/python3.9/site-packages/django/utils/deprecation.py", line 136, in __call__
    response = self.process_response(request, response)
  File "/usr/local/lib/python3.9/site-packages/django/middleware/common.py", line 108, in process_response
    return self.response_redirect_class(self.get_full_path_with_slash(request))
  File "/usr/local/lib/python3.9/site-packages/django/middleware/common.py", line 87, in get_full_path_with_slash
    raise RuntimeError(
RuntimeError: You called this URL via PUT, but the URL doesn't end in a slash and you have APPEND_SLASH set. Django can't redirect to the slash URL while maintaining PUT data. Change your form to point to localhost:7777/api/users/ (note the trailing slash), or set APPEND_SLASH=False in your Django settings.
"PUT /api/users HTTP/1.1" 500 62510
Internal Server Error: /api/users/c3daef55-72c6-4cc5-8924-616063dd51c8
Traceback (most recent call last):
  File "/usr/local/lib/python3.9/site-packages/django/core/handlers/exception.py", line 55, in inner
    response = get_response(request)
  File "/usr/local/lib/python3.9/site-packages/django/utils/deprecation.py", line 136, in __call__
    response = self.process_response(request, response)
  File "/usr/local/lib/python3.9/site-packages/django/middleware/common.py", line 108, in process_response
    return self.response_redirect_class(self.get_full_path_with_slash(request))
  File "/usr/local/lib/python3.9/site-packages/django/middleware/common.py", line 87, in get_full_path_with_slash
    raise RuntimeError(
RuntimeError: You called this URL via PUT, but the URL doesn't end in a slash and you have APPEND_SLASH set. Django can't redirect to the slash URL while maintaining PUT data. Change your form to point to localhost:7777/api/users/c3daef55-72c6-4cc5-8924-616063dd51c8/ (note the trailing slash), or set APPEND_SLASH=False in your Django settings.
"PUT /api/users/c3daef55-72c6-4cc5-8924-616063dd51c8 HTTP/1.1" 500 63102
Internal Server Error: /api/suppliers/
Traceback (most recent call last):
  File "/usr/local/lib/python3.9/site-packages/django/core/handlers/exception.py", line 55, in inner
    response = get_response(request)
  File "/usr/local/lib/python3.9/site-packages/django/core/handlers/base.py", line 197, in _get_response
    response = wrapped_callback(request, *callback_args, **callback_kwargs)
  File "/usr/local/lib/python3.9/site-packages/django/views/decorators/csrf.py", line 56, in wrapper_view
    return view_func(*args, **kwargs)
  File "/usr/local/lib/python3.9/site-packages/rest_framework/viewsets.py", line 125, in view
    return self.dispatch(request, *args, **kwargs)
  File "/usr/local/lib/python3.9/site-packages/rest_framework/views.py", line 509, in dispatch
    response = self.handle_exception(exc)
  File "/usr/local/lib/python3.9/site-packages/rest_framework/views.py", line 469, in handle_exception
    self.raise_uncaught_exception(exc)
  File "/usr/local/lib/python3.9/site-packages/rest_framework/views.py", line 480, in raise_uncaught_exception
    raise exc
  File "/usr/local/lib/python3.9/site-packages/rest_framework/views.py", line 506, in dispatch
    response = handler(request, *args, **kwargs)
  File "/usr/local/lib/python3.9/site-packages/rest_framework/mixins.py", line 18, in create
    serializer.is_valid(raise_exception=True)
  File "/usr/local/lib/python3.9/site-packages/rest_framework/serializers.py", line 227, in is_valid
    self._validated_data = self.run_validation(self.initial_data)
  File "/usr/local/lib/python3.9/site-packages/rest_framework/serializers.py", line 426, in run_validation
    value = self.to_internal_value(data)
  File "/usr/local/lib/python3.9/site-packages/rest_framework/serializers.py", line 479, in to_internal_value
    for field in fields:
  File "/usr/local/lib/python3.9/site-packages/rest_framework/serializers.py", line 362, in _writable_fields
    for field in self.fields.values():
  File "/usr/local/lib/python3.9/site-packages/django/utils/functional.py", line 57, in __get__
    res = instance.__dict__[self.name] = self.func(instance)
  File "/usr/local/lib/python3.9/site-packages/rest_framework/serializers.py", line 356, in fields
    for key, value in self.get_fields().items():
  File "/usr/local/lib/python3.9/site-packages/rest_framework/serializers.py", line 1076, in get_fields
    field_class, field_kwargs = self.build_field(
  File "/usr/local/lib/python3.9/site-packages/rest_framework/serializers.py", line 1222, in build_field
    return self.build_unknown_field(field_name, model_class)
  File "/usr/local/lib/python3.9/site-packages/rest_framework/serializers.py", line 1340, in build_unknown_field
    raise ImproperlyConfigured(
django.core.exceptions.ImproperlyConfigured: Field name `s_name` is not valid for model `Supplier`.
"POST /api/suppliers/ HTTP/1.1" 500 133830
Internal Server Error: /api/suppliers/
Traceback (most recent call last):
  File "/usr/local/lib/python3.9/site-packages/django/core/handlers/exception.py", line 55, in inner
    response = get_response(request)
  File "/usr/local/lib/python3.9/site-packages/django/core/handlers/base.py", line 197, in _get_response
    response = wrapped_callback(request, *callback_args, **callback_kwargs)
  File "/usr/local/lib/python3.9/site-packages/django/views/decorators/csrf.py", line 56, in wrapper_view
    return view_func(*args, **kwargs)
  File "/usr/local/lib/python3.9/site-packages/rest_framework/viewsets.py", line 125, in view
    return self.dispatch(request, *args, **kwargs)
  File "/usr/local/lib/python3.9/site-packages/rest_framework/views.py", line 509, in dispatch
    response = self.handle_exception(exc)
  File "/usr/local/lib/python3.9/site-packages/rest_framework/views.py", line 469, in handle_exception
    self.raise_uncaught_exception(exc)
  File "/usr/local/lib/python3.9/site-packages/rest_framework/views.py", line 480, in raise_uncaught_exception
    raise exc
  File "/usr/local/lib/python3.9/site-packages/rest_framework/views.py", line 506, in dispatch
    response = handler(request, *args, **kwargs)
  File "/usr/local/lib/python3.9/site-packages/rest_framework/mixins.py", line 18, in create
    serializer.is_valid(raise_exception=True)
  File "/usr/local/lib/python3.9/site-packages/rest_framework/serializers.py", line 227, in is_valid
    self._validated_data = self.run_validation(self.initial_data)
  File "/usr/local/lib/python3.9/site-packages/rest_framework/serializers.py", line 426, in run_validation
    value = self.to_internal_value(data)
  File "/usr/local/lib/python3.9/site-packages/rest_framework/serializers.py", line 479, in to_internal_value
    for field in fields:
  File "/usr/local/lib/python3.9/site-packages/rest_framework/serializers.py", line 362, in _writable_fields
    for field in self.fields.values():
  File "/usr/local/lib/python3.9/site-packages/django/utils/functional.py", line 57, in __get__
    res = instance.__dict__[self.name] = self.func(instance)
  File "/usr/local/lib/python3.9/site-packages/rest_framework/serializers.py", line 356, in fields
    for key, value in self.get_fields().items():
  File "/usr/local/lib/python3.9/site-packages/rest_framework/serializers.py", line 1076, in get_fields
    field_class, field_kwargs = self.build_field(
  File "/usr/local/lib/python3.9/site-packages/rest_framework/serializers.py", line 1222, in build_field
    return self.build_unknown_field(field_name, model_class)
  File "/usr/local/lib/python3.9/site-packages/rest_framework/serializers.py", line 1340, in build_unknown_field
    raise ImproperlyConfigured(
django.core.exceptions.ImproperlyConfigured: Field name `s_name` is not valid for model `Supplier`.
"POST /api/suppliers/ HTTP/1.1" 500 133830
Internal Server Error: /
Traceback (most recent call last):
  File "/usr/local/lib/python3.9/site-packages/django/core/handlers/exception.py", line 55, in inner
    response = get_response(request)
  File "/usr/local/lib/python3.9/site-packages/django/core/handlers/base.py", line 197, in _get_response
    response = wrapped_callback(request, *callback_args, **callback_kwargs)
  File "/usr/local/lib/python3.9/site-packages/django/views/decorators/csrf.py", line 56, in wrapper_view
    return view_func(*args, **kwargs)
  File "/usr/local/lib/python3.9/site-packages/django/views/generic/base.py", line 104, in view
    return self.dispatch(request, *args, **kwargs)
  File "/usr/local/lib/python3.9/site-packages/rest_framework/views.py", line 509, in dispatch
    response = self.handle_exception(exc)
  File "/usr/local/lib/python3.9/site-packages/rest_framework/views.py", line 469, in handle_exception
    self.raise_uncaught_exception(exc)
  File "/usr/local/lib/python3.9/site-packages/rest_framework/views.py", line 480, in raise_uncaught_exception
    raise exc
  File "/usr/local/lib/python3.9/site-packages/rest_framework/views.py", line 506, in dispatch
    response = handler(request, *args, **kwargs)
  File "/usr/local/lib/python3.9/site-packages/drf_yasg/views.py", line 96, in get
    schema = generator.get_schema(request, self.public)
  File "/usr/local/lib/python3.9/site-packages/drf_yasg/generators.py", line 276, in get_schema
    paths, prefix = self.get_paths(endpoints, components, request, public)
  File "/usr/local/lib/python3.9/site-packages/drf_yasg/generators.py", line 482, in get_paths
    operation = self.get_operation(view, path, prefix, method, components, request)
  File "/usr/local/lib/python3.9/site-packages/drf_yasg/generators.py", line 524, in get_operation
    operation = view_inspector.get_operation(operation_keys)
  File "/usr/local/lib/python3.9/site-packages/drf_yasg/inspectors/view.py", line 45, in get_operation
    responses = self.get_responses()
  File "/usr/local/lib/python3.9/site-packages/drf_yasg/inspectors/view.py", line 180, in get_responses
    response_serializers = self.get_response_serializers()
  File "/usr/local/lib/python3.9/site-packages/drf_yasg/inspectors/view.py", line 235, in get_response_serializers
    responses = self.get_default_responses()
  File "/usr/local/lib/python3.9/site-packages/drf_yasg/inspectors/view.py", line 211, in get_default_responses
    default_schema = self.serializer_to_schema(default_schema) or ''
  File "/usr/local/lib/python3.9/site-packages/drf_yasg/inspectors/base.py", line 438, in serializer_to_schema
    return self.probe_inspectors(
  File "/usr/local/lib/python3.9/site-packages/drf_yasg/inspectors/base.py", line 110, in probe_inspectors
    result = method(obj, **kwargs)
  File "/usr/local/lib/python3.9/site-packages/drf_yasg/inspectors/field.py", line 42, in get_schema
    return self.probe_field_inspectors(serializer, openapi.Schema, self.use_definitions)
  File "/usr/local/lib/python3.9/site-packages/drf_yasg/inspectors/base.py", line 228, in probe_field_inspectors
    return self.probe_inspectors(
  File "/usr/local/lib/python3.9/site-packages/drf_yasg/inspectors/base.py", line 110, in probe_inspectors
    result = method(obj, **kwargs)
  File "/usr/local/lib/python3.9/site-packages/drf_yasg/inspectors/field.py", line 133, in field_to_swagger_object
    actual_schema = definitions.setdefault(ref_name, make_schema_definition)
  File "/usr/local/lib/python3.9/site-packages/drf_yasg/openapi.py", line 685, in setdefault
    ret = maker()
  File "/usr/local/lib/python3.9/site-packages/drf_yasg/inspectors/field.py", line 102, in make_schema_definition
    for property_name, child in serializer.fields.items():
  File "/usr/local/lib/python3.9/site-packages/django/utils/functional.py", line 57, in __get__
    res = instance.__dict__[self.name] = self.func(instance)
  File "/usr/local/lib/python3.9/site-packages/rest_framework/serializers.py", line 356, in fields
    for key, value in self.get_fields().items():
  File "/usr/local/lib/python3.9/site-packages/rest_framework/serializers.py", line 1076, in get_fields
    field_class, field_kwargs = self.build_field(
  File "/usr/local/lib/python3.9/site-packages/rest_framework/serializers.py", line 1222, in build_field
    return self.build_unknown_field(field_name, model_class)
  File "/usr/local/lib/python3.9/site-packages/rest_framework/serializers.py", line 1340, in build_unknown_field
    raise ImproperlyConfigured(
django.core.exceptions.ImproperlyConfigured: Field name `s_name` is not valid for model `Supplier`.
"GET /?format=openapi HTTP/1.1" 500 214176
